<?xml version="1.0" ?>

<robot name="my_mm_robot" xmlns:xacro="https://www.ros.org/wiki/xacro" >
  <xacro:property name="wheelRadius" value="0.05" /> 
  
  <gazebo reference="link_chassis">
    <material>Gazebo/Orange</material>
  </gazebo>
  <gazebo reference="link_left_wheel">
    <material>Gazebo/Black</material>
  </gazebo>
  <gazebo reference="link_right_wheel">
    <material>Gazebo/Black</material>
  </gazebo>
    
  <link name="link_chassis">
    <!-- pose and inertial -->
    <pose>0 0 0.1 0 0 0</pose>
    
    <inertial>
      <mass value="2"/>
      <origin rpy="0  0  0" xyz="0 0.01 0"/>
      <inertia ixx="0.00022083" ixy="0" ixz="0" iyy="0.00022083" iyz="0" izz="0.00040833"/>
    </inertial>
    
    <collision name="link_chassis_collision">
      <origin rpy="0  0  0" xyz="0     0    -0.00"/>
      <geometry>
        <box size="0.05 0.05 0.01"/>
      </geometry>
    </collision>
    
    <visual name="link_chassis_visual">
      <origin rpy="0  0  0" xyz="0     0    -0.00"/>
      <geometry>
        <box size="0.05 0.05 0.01"/>
      </geometry>
    </visual>
</link>
  
  <!-- Create wheel right -->  
    
  <link name="link_right_wheel">    
    <inertial>
      <mass value="0.5"/>
      <origin rpy="0 1.5707 0" xyz="0 0 0"/>
      <inertia ixx="1.15e-06" ixy="0" ixz="0" iyy="1.15e-06" iyz="0" izz="2.25e-07"/>
    </inertial>
    
    <collision name="link_right_wheel_collision">
      <origin rpy="0 1.5707 0" xyz="0 0 0"/>
      <geometry>
        <cylinder length="0.008" radius="${wheelRadius}"/>
      </geometry>
      <surface>
        <friction>
          <ode>
            <mu>100</mu>
            <mu2>100</mu2>
            <!-- <slip1>1000.0</slip1>
            <slip2>1000.0</slip2> -->
            <slip1>0.0</slip1>
            <slip2>0.0</slip2>
          </ode>
        </friction>
      </surface>
    </collision>
    
    <visual name="link_right_wheel_visual">
      <origin rpy="0 1.5707 0" xyz="0 0 0"/>
      <geometry>
        <cylinder length="0.008" radius="${wheelRadius}"/>
      </geometry>      
    </visual>
    
  </link>
    
  <!--   Joint for right wheel  -->
  <joint name="joint_right_wheel" type="continuous">
    <origin rpy="0 0 0" xyz="-0.04  0.0    -0.0"/>
    <child link="link_right_wheel" />
    <parent link="link_chassis"/>
    <axis rpy="0 0 0" xyz="1 0 0"/>
    <limit effort="5" velocity="6"/>
    <joint_properties damping="10000.0" friction="10000.0" />
  </joint>  
  <transmission name="right_wheel_trans">
     <type>transmission_interface/SimpleTransmission</type>
     <actuator name="right_wheel_motor">
       <hardwareInterface>VelocityJointInterface</hardwareInterface>
       <mechanicalReduction>7</mechanicalReduction>
     </actuator>
     <joint name="joint_right_wheel">
       <hardwareInterface>VelocityJointInterface</hardwareInterface>
     </joint>
  </transmission>
    
  <!-- Left Wheel link -->
    
  <link name="link_left_wheel">    
    <inertial>
      <mass value="0.5"/>
      <origin rpy="0 1.5707 0" xyz="0 0 0"/>
      <inertia ixx="1.15e-06" ixy="0" ixz="0" iyy="1.15e-06" iyz="0" izz="2.25e-07"/>
    </inertial>
    
    <collision name="link_left_wheel_collision">
      <origin rpy="0 1.5707 0" xyz="0 0 0"/>
      <geometry>
        <cylinder length="0.008" radius="${wheelRadius}"/>
      </geometry>
      <surface>
        <friction>
          <ode>
            <mu>100</mu>
            <mu2>100</mu2>
            <!-- <slip1>1000.0</slip1>
            <slip2>1000.0</slip2> -->
            <slip1>0.0</slip1>
            <slip2>0.0</slip2>
          </ode>
        </friction>
      </surface>
    </collision>
    
    <visual name="link_left_wheel_visual">
      <origin rpy="0 1.5707 0" xyz="0 0 0"/>
      <geometry>
        <cylinder length="0.008" radius="${wheelRadius}"/>
      </geometry>      
    </visual>
    
  </link>
    
  <!--   Joint for right wheel  -->
  <joint name="joint_left_wheel" type="continuous">
    <origin rpy="0 0 0" xyz="0.04 0.0 -0.0"/>
    <child link="link_left_wheel" />
    <parent link="link_chassis"/>
    <axis rpy="0 0 0" xyz="1 0 0"/>
    <limit effort="5" velocity="6"/>
    <joint_properties damping="10000.0" friction="10000.0" />
  </joint> 
  <transmission name="left_wheel_trans">
     <type>transmission_interface/SimpleTransmission</type>
     <actuator name="left_wheel_motor">
       <hardwareInterface>VelocityJointInterface</hardwareInterface>
       <mechanicalReduction>7</mechanicalReduction>
     </actuator>
     <joint name="joint_left_wheel">
       <hardwareInterface>VelocityJointInterface</hardwareInterface>
     </joint>
  </transmission>


  <gazebo>
    <plugin filename="libgazebo_ros_diff_drive.so" name="differential_drive_controller">
      <alwaysOn>true</alwaysOn>
      <legacyMode>false</legacyMode>
      <updateRate>20</updateRate>
      <leftJoint>joint_left_wheel</leftJoint>
      <rightJoint>joint_right_wheel</rightJoint>
      <wheelSeparation>0.4</wheelSeparation>
      <wheelDiameter>0.2</wheelDiameter>
      <torque>0.0</torque>
      <commandTopic>cmd_vel</commandTopic>
      <odometryTopic>odom</odometryTopic>
      <odometryFrame>odom</odometryFrame>
      <robotBaseFrame>link_chassis</robotBaseFrame>
    </plugin>
  </gazebo>

  <!-- <gazebo> 
    <plugin name="gazebo_ros_control" filename="libgazebo_ros_control.so">
      <robotNamespace>/simple_model</robotNamespace>
      <legacyModeNS>true</legacyModeNS>
      <robotSimType>gazebo_ros_control/DefaultRobotHWSim</robotSimType>
    </plugin>
  </gazebo>-->
  
</robot>
